Traceback (most recent call last):
  File "/Library/Frameworks/Python.framework/Versions/3.8/lib/python3.8/site-packages/jupyter_cache/executors/utils.py", line 51, in single_nb_execution
    executenb(
  File "/Library/Frameworks/Python.framework/Versions/3.8/lib/python3.8/site-packages/nbclient/client.py", line 1087, in execute
    return NotebookClient(nb=nb, resources=resources, km=km, **kwargs).execute()
  File "/Library/Frameworks/Python.framework/Versions/3.8/lib/python3.8/site-packages/nbclient/util.py", line 74, in wrapped
    return just_run(coro(*args, **kwargs))
  File "/Library/Frameworks/Python.framework/Versions/3.8/lib/python3.8/site-packages/nbclient/util.py", line 53, in just_run
    return loop.run_until_complete(coro)
  File "/Library/Frameworks/Python.framework/Versions/3.8/lib/python3.8/asyncio/base_events.py", line 616, in run_until_complete
    return future.result()
  File "/Library/Frameworks/Python.framework/Versions/3.8/lib/python3.8/site-packages/nbclient/client.py", line 540, in async_execute
    await self.async_execute_cell(
  File "/Library/Frameworks/Python.framework/Versions/3.8/lib/python3.8/site-packages/nbclient/client.py", line 832, in async_execute_cell
    self._check_raise_for_error(cell, exec_reply)
  File "/Library/Frameworks/Python.framework/Versions/3.8/lib/python3.8/site-packages/nbclient/client.py", line 740, in _check_raise_for_error
    raise CellExecutionError.from_cell_and_msg(cell, exec_reply['content'])
nbclient.exceptions.CellExecutionError: An error occurred while executing the following cell:
------------------
sc = StandardScaler(ddof=1)
------------------

[0;31m---------------------------------------------------------------------------[0m
[0;31mTypeError[0m                                 Traceback (most recent call last)
[0;32m<ipython-input-7-b7f933efb042>[0m in [0;36m<module>[0;34m[0m
[0;32m----> 1[0;31m [0msc[0m [0;34m=[0m [0mStandardScaler[0m[0;34m([0m[0mddof[0m[0;34m=[0m[0;36m1[0m[0;34m)[0m[0;34m[0m[0;34m[0m[0m
[0m
[0;32m/Library/Frameworks/Python.framework/Versions/3.8/lib/python3.8/site-packages/sklearn/utils/validation.py[0m in [0;36minner_f[0;34m(*args, **kwargs)[0m
[1;32m     61[0m             [0mextra_args[0m [0;34m=[0m [0mlen[0m[0;34m([0m[0margs[0m[0;34m)[0m [0;34m-[0m [0mlen[0m[0;34m([0m[0mall_args[0m[0;34m)[0m[0;34m[0m[0;34m[0m[0m
[1;32m     62[0m             [0;32mif[0m [0mextra_args[0m [0;34m<=[0m [0;36m0[0m[0;34m:[0m[0;34m[0m[0;34m[0m[0m
[0;32m---> 63[0;31m                 [0;32mreturn[0m [0mf[0m[0;34m([0m[0;34m*[0m[0margs[0m[0;34m,[0m [0;34m**[0m[0mkwargs[0m[0;34m)[0m[0;34m[0m[0;34m[0m[0m
[0m[1;32m     64[0m [0;34m[0m[0m
[1;32m     65[0m             [0;31m# extra_args > 0[0m[0;34m[0m[0;34m[0m[0;34m[0m[0m

[0;31mTypeError[0m: __init__() got an unexpected keyword argument 'ddof'
TypeError: __init__() got an unexpected keyword argument 'ddof'

